2024-07-17 08:45:18,602 INFO    MainThread:12094 [wandb_setup.py:_flush():76] Current SDK version is 0.16.6
2024-07-17 08:45:18,603 INFO    MainThread:12094 [wandb_setup.py:_flush():76] Configure stats pid to 12094
2024-07-17 08:45:18,603 INFO    MainThread:12094 [wandb_setup.py:_flush():76] Loading settings from /home/fmri/.config/wandb/settings
2024-07-17 08:45:18,603 INFO    MainThread:12094 [wandb_setup.py:_flush():76] Loading settings from /media/SSD_1_2T/xt/MindBridge/src/wandb/settings
2024-07-17 08:45:18,603 INFO    MainThread:12094 [wandb_setup.py:_flush():76] Loading settings from environment variables: {'api_key': '***REDACTED***'}
2024-07-17 08:45:18,603 INFO    MainThread:12094 [wandb_setup.py:_flush():76] Inferring run settings from compute environment: {'program_relpath': 'src/main.py', 'program_abspath': '/media/SSD_1_2T/xt/MindBridge/src/main.py', 'program': '/media/SSD_1_2T/xt/MindBridge/src/main.py'}
2024-07-17 08:45:18,603 INFO    MainThread:12094 [wandb_setup.py:_flush():76] Applying login settings: {'base_url': 'https://api.wandb.ai'}
2024-07-17 08:45:18,603 INFO    MainThread:12094 [wandb_setup.py:_flush():76] Applying login settings: {}
2024-07-17 08:45:18,603 INFO    MainThread:12094 [wandb_init.py:_log_setup():521] Logging user logs to /media/SSD_1_2T/xt/MindBridge/src/wandb/run-20240717_084518-6pdv0ekb/logs/debug.log
2024-07-17 08:45:18,603 INFO    MainThread:12094 [wandb_init.py:_log_setup():522] Logging internal logs to /media/SSD_1_2T/xt/MindBridge/src/wandb/run-20240717_084518-6pdv0ekb/logs/debug-internal.log
2024-07-17 08:45:18,603 INFO    MainThread:12094 [wandb_init.py:init():561] calling init triggers
2024-07-17 08:45:18,603 INFO    MainThread:12094 [wandb_init.py:init():568] wandb.init called with sweep_config: {}
config: {'trainer_select': 'trainer_fmri_text', 'model_name': 'MindBrige_text_only_mixco_loss', 'data_path': '/media/SSD_1_2T/xt/data/natural-scenes-dataset', 'subj_list': [1, 2, 5, 7], 'subj_source': [1], 'subj_target': [1], 'adapting': False, 'batch_size': 250, 'val_batch_size': 50, 'clip_variant': 'ViT-L/14', 'wandb_log': True, 'wandb_project': 'MindBrige_text_only_mixco_loss', 'resume': False, 'resume_id': None, 'load_from': None, 'norm_embs': True, 'use_image_aug': True, 'num_epochs': 500, 'lr_scheduler_type': 'cycle', 'ckpt_interval': 1, 'eval_interval': 1, 'h_size': 2048, 'n_blocks': 4, 'seed': 42, 'num_workers': 4, 'max_lr': 0.0005, 'mixup_pct': 0.2, 'pool_num': 8192, 'pool_type': 'max', 'mse_mult': 100000.0, 'mae_mult': 10000.0, 'rec_mult': 1.0, 'cyc_mult': 1.0, 'nce_mult': 1.0, 'clip_mult': 10, 'length': None, 'autoencoder_name': None, 'subj_load': None, 'subj_test': 1, 'samples': None, 'img2img_strength': 0.85, 'guidance_scale': 3.5, 'num_inference_steps': 20, 'recons_per_sample': 16, 'plotting': True, 'diffusion_cache_dir': '../weights', 'gpu_id': 0, 'ckpt_from': 'last', 'text_image_ratio': 0.5, 'test_start': 0, 'test_end': None, 'only_embeddings': False, 'synthesis': False, 'verbose': True, 'results_path': None}
2024-07-17 08:45:18,603 INFO    MainThread:12094 [wandb_init.py:init():611] starting backend
2024-07-17 08:45:18,603 INFO    MainThread:12094 [wandb_init.py:init():615] setting up manager
2024-07-17 08:45:18,605 INFO    MainThread:12094 [backend.py:_multiprocessing_setup():105] multiprocessing start_methods=fork,spawn,forkserver, using: spawn
2024-07-17 08:45:18,607 INFO    MainThread:12094 [wandb_init.py:init():623] backend started and connected
2024-07-17 08:45:18,610 INFO    MainThread:12094 [wandb_init.py:init():715] updated telemetry
2024-07-17 08:45:18,614 INFO    MainThread:12094 [wandb_init.py:init():748] communicating run to backend with 90.0 second timeout
2024-07-17 08:46:20,239 INFO    Thread-1 (wrapped_target):12094 [retry.py:__call__():172] Retry attempt failed:
Traceback (most recent call last):
  File "/home/fmri/miniconda3/envs/xt/lib/python3.10/site-packages/urllib3/connectionpool.py", line 536, in _make_request
    response = conn.getresponse()
  File "/home/fmri/miniconda3/envs/xt/lib/python3.10/site-packages/urllib3/connection.py", line 464, in getresponse
    httplib_response = super().getresponse()
  File "/home/fmri/miniconda3/envs/xt/lib/python3.10/http/client.py", line 1375, in getresponse
    response.begin()
  File "/home/fmri/miniconda3/envs/xt/lib/python3.10/http/client.py", line 318, in begin
    version, status, reason = self._read_status()
  File "/home/fmri/miniconda3/envs/xt/lib/python3.10/http/client.py", line 279, in _read_status
    line = str(self.fp.readline(_MAXLINE + 1), "iso-8859-1")
  File "/home/fmri/miniconda3/envs/xt/lib/python3.10/socket.py", line 705, in readinto
    return self._sock.recv_into(b)
  File "/home/fmri/miniconda3/envs/xt/lib/python3.10/ssl.py", line 1307, in recv_into
    return self.read(nbytes, buffer)
  File "/home/fmri/miniconda3/envs/xt/lib/python3.10/ssl.py", line 1163, in read
    return self._sslobj.read(len, buffer)
TimeoutError: The read operation timed out

The above exception was the direct cause of the following exception:

Traceback (most recent call last):
  File "/home/fmri/miniconda3/envs/xt/lib/python3.10/site-packages/requests/adapters.py", line 667, in send
    resp = conn.urlopen(
  File "/home/fmri/miniconda3/envs/xt/lib/python3.10/site-packages/urllib3/connectionpool.py", line 843, in urlopen
    retries = retries.increment(
  File "/home/fmri/miniconda3/envs/xt/lib/python3.10/site-packages/urllib3/util/retry.py", line 474, in increment
    raise reraise(type(error), error, _stacktrace)
  File "/home/fmri/miniconda3/envs/xt/lib/python3.10/site-packages/urllib3/util/util.py", line 39, in reraise
    raise value
  File "/home/fmri/miniconda3/envs/xt/lib/python3.10/site-packages/urllib3/connectionpool.py", line 789, in urlopen
    response = self._make_request(
  File "/home/fmri/miniconda3/envs/xt/lib/python3.10/site-packages/urllib3/connectionpool.py", line 538, in _make_request
    self._raise_timeout(err=e, url=url, timeout_value=read_timeout)
  File "/home/fmri/miniconda3/envs/xt/lib/python3.10/site-packages/urllib3/connectionpool.py", line 369, in _raise_timeout
    raise ReadTimeoutError(
urllib3.exceptions.ReadTimeoutError: HTTPSConnectionPool(host='api.wandb.ai', port=443): Read timed out. (read timeout=20)

During handling of the above exception, another exception occurred:

Traceback (most recent call last):
  File "/home/fmri/miniconda3/envs/xt/lib/python3.10/site-packages/wandb/sdk/lib/retry.py", line 131, in __call__
    result = self._call_fn(*args, **kwargs)
  File "/home/fmri/miniconda3/envs/xt/lib/python3.10/site-packages/wandb/sdk/internal/internal_api.py", line 369, in execute
    return self.client.execute(*args, **kwargs)  # type: ignore
  File "/home/fmri/miniconda3/envs/xt/lib/python3.10/site-packages/wandb/vendor/gql-0.2.0/wandb_gql/client.py", line 52, in execute
    result = self._get_result(document, *args, **kwargs)
  File "/home/fmri/miniconda3/envs/xt/lib/python3.10/site-packages/wandb/vendor/gql-0.2.0/wandb_gql/client.py", line 60, in _get_result
    return self.transport.execute(document, *args, **kwargs)
  File "/home/fmri/miniconda3/envs/xt/lib/python3.10/site-packages/wandb/sdk/lib/gql_request.py", line 58, in execute
    request = self.session.post(self.url, **post_args)
  File "/home/fmri/miniconda3/envs/xt/lib/python3.10/site-packages/requests/sessions.py", line 637, in post
    return self.request("POST", url, data=data, json=json, **kwargs)
  File "/home/fmri/miniconda3/envs/xt/lib/python3.10/site-packages/requests/sessions.py", line 589, in request
    resp = self.send(prep, **send_kwargs)
  File "/home/fmri/miniconda3/envs/xt/lib/python3.10/site-packages/requests/sessions.py", line 703, in send
    r = adapter.send(request, **kwargs)
  File "/home/fmri/miniconda3/envs/xt/lib/python3.10/site-packages/requests/adapters.py", line 713, in send
    raise ReadTimeout(e, request=request)
requests.exceptions.ReadTimeout: HTTPSConnectionPool(host='api.wandb.ai', port=443): Read timed out. (read timeout=20)
2024-07-17 08:46:48,647 ERROR   MainThread:12094 [wandb_init.py:init():774] encountered error: Run initialization has timed out after 90.0 sec. 
Please refer to the documentation for additional information: https://docs.wandb.ai/guides/track/tracking-faq#initstarterror-error-communicating-with-wandb-process-
2024-07-17 08:46:49,343 ERROR   MainThread:12094 [wandb_init.py:init():1199] Run initialization has timed out after 90.0 sec. 
Please refer to the documentation for additional information: https://docs.wandb.ai/guides/track/tracking-faq#initstarterror-error-communicating-with-wandb-process-
Traceback (most recent call last):
  File "/home/fmri/miniconda3/envs/xt/lib/python3.10/site-packages/wandb/sdk/wandb_init.py", line 1181, in init
    run = wi.init()
  File "/home/fmri/miniconda3/envs/xt/lib/python3.10/site-packages/wandb/sdk/wandb_init.py", line 780, in init
    raise error
wandb.errors.CommError: Run initialization has timed out after 90.0 sec. 
Please refer to the documentation for additional information: https://docs.wandb.ai/guides/track/tracking-faq#initstarterror-error-communicating-with-wandb-process-
2024-07-17 08:46:50,347 WARNING MsgRouterThr:12094 [router.py:message_loop():77] message_loop has been closed
