2024-07-17 08:45:18,608 INFO    StreamThr :12276 [internal.py:wandb_internal():86] W&B internal server running at pid: 12276, started at: 2024-07-17 08:45:18.607837
2024-07-17 08:45:18,610 DEBUG   HandlerThread:12276 [handler.py:handle_request():146] handle_request: status
2024-07-17 08:45:18,613 INFO    WriterThread:12276 [datastore.py:open_for_write():87] open: /media/SSD_1_2T/xt/MindBridge/src/wandb/run-20240717_084518-6pdv0ekb/run-6pdv0ekb.wandb
2024-07-17 08:45:18,613 DEBUG   SenderThread:12276 [sender.py:send():379] send: header
2024-07-17 08:45:18,615 DEBUG   SenderThread:12276 [sender.py:send():379] send: run
2024-07-17 08:45:23,617 DEBUG   HandlerThread:12276 [handler.py:handle_request():146] handle_request: keepalive
2024-07-17 08:45:28,619 DEBUG   HandlerThread:12276 [handler.py:handle_request():146] handle_request: keepalive
2024-07-17 08:45:33,620 DEBUG   HandlerThread:12276 [handler.py:handle_request():146] handle_request: keepalive
2024-07-17 08:45:38,621 DEBUG   HandlerThread:12276 [handler.py:handle_request():146] handle_request: keepalive
2024-07-17 08:45:43,623 DEBUG   HandlerThread:12276 [handler.py:handle_request():146] handle_request: keepalive
2024-07-17 08:45:48,625 DEBUG   HandlerThread:12276 [handler.py:handle_request():146] handle_request: keepalive
2024-07-17 08:45:53,627 DEBUG   HandlerThread:12276 [handler.py:handle_request():146] handle_request: keepalive
2024-07-17 08:45:58,629 DEBUG   HandlerThread:12276 [handler.py:handle_request():146] handle_request: keepalive
2024-07-17 08:46:03,631 DEBUG   HandlerThread:12276 [handler.py:handle_request():146] handle_request: keepalive
2024-07-17 08:46:08,632 DEBUG   HandlerThread:12276 [handler.py:handle_request():146] handle_request: keepalive
2024-07-17 08:46:13,634 DEBUG   HandlerThread:12276 [handler.py:handle_request():146] handle_request: keepalive
2024-07-17 08:46:18,636 DEBUG   HandlerThread:12276 [handler.py:handle_request():146] handle_request: keepalive
2024-07-17 08:46:21,912 INFO    SenderThread:12276 [retry.py:__call__():172] Retry attempt failed:
Traceback (most recent call last):
  File "/home/fmri/miniconda3/envs/xt/lib/python3.10/site-packages/urllib3/connection.py", line 196, in _new_conn
    sock = connection.create_connection(
  File "/home/fmri/miniconda3/envs/xt/lib/python3.10/site-packages/urllib3/util/connection.py", line 85, in create_connection
    raise err
  File "/home/fmri/miniconda3/envs/xt/lib/python3.10/site-packages/urllib3/util/connection.py", line 73, in create_connection
    sock.connect(sa)
TimeoutError: timed out

The above exception was the direct cause of the following exception:

Traceback (most recent call last):
  File "/home/fmri/miniconda3/envs/xt/lib/python3.10/site-packages/urllib3/connectionpool.py", line 789, in urlopen
    response = self._make_request(
  File "/home/fmri/miniconda3/envs/xt/lib/python3.10/site-packages/urllib3/connectionpool.py", line 490, in _make_request
    raise new_e
  File "/home/fmri/miniconda3/envs/xt/lib/python3.10/site-packages/urllib3/connectionpool.py", line 466, in _make_request
    self._validate_conn(conn)
  File "/home/fmri/miniconda3/envs/xt/lib/python3.10/site-packages/urllib3/connectionpool.py", line 1095, in _validate_conn
    conn.connect()
  File "/home/fmri/miniconda3/envs/xt/lib/python3.10/site-packages/urllib3/connection.py", line 615, in connect
    self.sock = sock = self._new_conn()
  File "/home/fmri/miniconda3/envs/xt/lib/python3.10/site-packages/urllib3/connection.py", line 205, in _new_conn
    raise ConnectTimeoutError(
urllib3.exceptions.ConnectTimeoutError: (<urllib3.connection.HTTPSConnection object at 0x7fd784121e40>, 'Connection to api.wandb.ai timed out. (connect timeout=20)')

The above exception was the direct cause of the following exception:

Traceback (most recent call last):
  File "/home/fmri/miniconda3/envs/xt/lib/python3.10/site-packages/requests/adapters.py", line 667, in send
    resp = conn.urlopen(
  File "/home/fmri/miniconda3/envs/xt/lib/python3.10/site-packages/urllib3/connectionpool.py", line 843, in urlopen
    retries = retries.increment(
  File "/home/fmri/miniconda3/envs/xt/lib/python3.10/site-packages/urllib3/util/retry.py", line 519, in increment
    raise MaxRetryError(_pool, url, reason) from reason  # type: ignore[arg-type]
urllib3.exceptions.MaxRetryError: HTTPSConnectionPool(host='api.wandb.ai', port=443): Max retries exceeded with url: /graphql (Caused by ConnectTimeoutError(<urllib3.connection.HTTPSConnection object at 0x7fd784121e40>, 'Connection to api.wandb.ai timed out. (connect timeout=20)'))

During handling of the above exception, another exception occurred:

Traceback (most recent call last):
  File "/home/fmri/miniconda3/envs/xt/lib/python3.10/site-packages/wandb/sdk/lib/retry.py", line 131, in __call__
    result = self._call_fn(*args, **kwargs)
  File "/home/fmri/miniconda3/envs/xt/lib/python3.10/site-packages/wandb/sdk/internal/internal_api.py", line 369, in execute
    return self.client.execute(*args, **kwargs)  # type: ignore
  File "/home/fmri/miniconda3/envs/xt/lib/python3.10/site-packages/wandb/vendor/gql-0.2.0/wandb_gql/client.py", line 52, in execute
    result = self._get_result(document, *args, **kwargs)
  File "/home/fmri/miniconda3/envs/xt/lib/python3.10/site-packages/wandb/vendor/gql-0.2.0/wandb_gql/client.py", line 60, in _get_result
    return self.transport.execute(document, *args, **kwargs)
  File "/home/fmri/miniconda3/envs/xt/lib/python3.10/site-packages/wandb/sdk/lib/gql_request.py", line 58, in execute
    request = self.session.post(self.url, **post_args)
  File "/home/fmri/miniconda3/envs/xt/lib/python3.10/site-packages/requests/sessions.py", line 637, in post
    return self.request("POST", url, data=data, json=json, **kwargs)
  File "/home/fmri/miniconda3/envs/xt/lib/python3.10/site-packages/requests/sessions.py", line 589, in request
    resp = self.send(prep, **send_kwargs)
  File "/home/fmri/miniconda3/envs/xt/lib/python3.10/site-packages/requests/sessions.py", line 703, in send
    r = adapter.send(request, **kwargs)
  File "/home/fmri/miniconda3/envs/xt/lib/python3.10/site-packages/requests/adapters.py", line 688, in send
    raise ConnectTimeout(e, request=request)
requests.exceptions.ConnectTimeout: HTTPSConnectionPool(host='api.wandb.ai', port=443): Max retries exceeded with url: /graphql (Caused by ConnectTimeoutError(<urllib3.connection.HTTPSConnection object at 0x7fd784121e40>, 'Connection to api.wandb.ai timed out. (connect timeout=20)'))
2024-07-17 08:46:23,638 DEBUG   HandlerThread:12276 [handler.py:handle_request():146] handle_request: keepalive
2024-07-17 08:46:28,640 DEBUG   HandlerThread:12276 [handler.py:handle_request():146] handle_request: keepalive
2024-07-17 08:46:33,641 DEBUG   HandlerThread:12276 [handler.py:handle_request():146] handle_request: keepalive
2024-07-17 08:46:38,643 DEBUG   HandlerThread:12276 [handler.py:handle_request():146] handle_request: keepalive
2024-07-17 08:46:43,645 DEBUG   HandlerThread:12276 [handler.py:handle_request():146] handle_request: keepalive
2024-07-17 08:46:48,647 DEBUG   HandlerThread:12276 [handler.py:handle_request():146] handle_request: cancel
2024-07-17 08:46:48,647 DEBUG   HandlerThread:12276 [handler.py:handle_request():146] handle_request: cancel
2024-07-17 08:46:48,648 DEBUG   SenderThread:12276 [sender.py:send():388] Record cancelled: run
2024-07-17 08:46:48,648 DEBUG   HandlerThread:12276 [handler.py:handle_request():146] handle_request: status_report
2024-07-17 08:46:49,345 DEBUG   HandlerThread:12276 [handler.py:handle_request():146] handle_request: shutdown
2024-07-17 08:46:49,346 INFO    HandlerThread:12276 [handler.py:finish():866] shutting down handler
2024-07-17 08:46:49,648 INFO    SenderThread:12276 [sender.py:finish():1546] shutting down sender
2024-07-17 08:46:49,649 INFO    WriterThread:12276 [datastore.py:close():296] close: /media/SSD_1_2T/xt/MindBridge/src/wandb/run-20240717_084518-6pdv0ekb/run-6pdv0ekb.wandb
