2024-07-17 09:52:03,309 INFO    StreamThr :171558 [internal.py:wandb_internal():86] W&B internal server running at pid: 171558, started at: 2024-07-17 09:52:03.309570
2024-07-17 09:52:03,311 DEBUG   HandlerThread:171558 [handler.py:handle_request():146] handle_request: status
2024-07-17 09:52:03,311 INFO    WriterThread:171558 [datastore.py:open_for_write():87] open: /media/SSD_1_2T/xt/MindBridge/src/wandb/run-20240717_095203-mi6gcdwu/run-mi6gcdwu.wandb
2024-07-17 09:52:03,311 DEBUG   SenderThread:171558 [sender.py:send():379] send: header
2024-07-17 09:52:03,312 DEBUG   SenderThread:171558 [sender.py:send():379] send: run
2024-07-17 09:52:08,313 DEBUG   HandlerThread:171558 [handler.py:handle_request():146] handle_request: keepalive
2024-07-17 09:52:13,314 DEBUG   HandlerThread:171558 [handler.py:handle_request():146] handle_request: keepalive
2024-07-17 09:52:18,315 DEBUG   HandlerThread:171558 [handler.py:handle_request():146] handle_request: keepalive
2024-07-17 09:52:23,316 DEBUG   HandlerThread:171558 [handler.py:handle_request():146] handle_request: keepalive
2024-07-17 09:52:28,317 DEBUG   HandlerThread:171558 [handler.py:handle_request():146] handle_request: keepalive
2024-07-17 09:52:33,318 DEBUG   HandlerThread:171558 [handler.py:handle_request():146] handle_request: keepalive
2024-07-17 09:52:38,319 DEBUG   HandlerThread:171558 [handler.py:handle_request():146] handle_request: keepalive
2024-07-17 09:52:43,320 DEBUG   HandlerThread:171558 [handler.py:handle_request():146] handle_request: keepalive
2024-07-17 09:52:48,321 DEBUG   HandlerThread:171558 [handler.py:handle_request():146] handle_request: keepalive
2024-07-17 09:52:53,322 DEBUG   HandlerThread:171558 [handler.py:handle_request():146] handle_request: keepalive
2024-07-17 09:52:58,322 DEBUG   HandlerThread:171558 [handler.py:handle_request():146] handle_request: keepalive
2024-07-17 09:53:03,323 DEBUG   HandlerThread:171558 [handler.py:handle_request():146] handle_request: keepalive
2024-07-17 09:53:07,033 INFO    SenderThread:171558 [retry.py:__call__():172] Retry attempt failed:
Traceback (most recent call last):
  File "/home/fmri/miniconda3/envs/xt/lib/python3.10/site-packages/urllib3/connection.py", line 196, in _new_conn
    sock = connection.create_connection(
  File "/home/fmri/miniconda3/envs/xt/lib/python3.10/site-packages/urllib3/util/connection.py", line 85, in create_connection
    raise err
  File "/home/fmri/miniconda3/envs/xt/lib/python3.10/site-packages/urllib3/util/connection.py", line 73, in create_connection
    sock.connect(sa)
TimeoutError: timed out

The above exception was the direct cause of the following exception:

Traceback (most recent call last):
  File "/home/fmri/miniconda3/envs/xt/lib/python3.10/site-packages/urllib3/connectionpool.py", line 789, in urlopen
    response = self._make_request(
  File "/home/fmri/miniconda3/envs/xt/lib/python3.10/site-packages/urllib3/connectionpool.py", line 490, in _make_request
    raise new_e
  File "/home/fmri/miniconda3/envs/xt/lib/python3.10/site-packages/urllib3/connectionpool.py", line 466, in _make_request
    self._validate_conn(conn)
  File "/home/fmri/miniconda3/envs/xt/lib/python3.10/site-packages/urllib3/connectionpool.py", line 1095, in _validate_conn
    conn.connect()
  File "/home/fmri/miniconda3/envs/xt/lib/python3.10/site-packages/urllib3/connection.py", line 615, in connect
    self.sock = sock = self._new_conn()
  File "/home/fmri/miniconda3/envs/xt/lib/python3.10/site-packages/urllib3/connection.py", line 205, in _new_conn
    raise ConnectTimeoutError(
urllib3.exceptions.ConnectTimeoutError: (<urllib3.connection.HTTPSConnection object at 0x7f5f3778de40>, 'Connection to api.wandb.ai timed out. (connect timeout=20)')

The above exception was the direct cause of the following exception:

Traceback (most recent call last):
  File "/home/fmri/miniconda3/envs/xt/lib/python3.10/site-packages/requests/adapters.py", line 667, in send
    resp = conn.urlopen(
  File "/home/fmri/miniconda3/envs/xt/lib/python3.10/site-packages/urllib3/connectionpool.py", line 843, in urlopen
    retries = retries.increment(
  File "/home/fmri/miniconda3/envs/xt/lib/python3.10/site-packages/urllib3/util/retry.py", line 519, in increment
    raise MaxRetryError(_pool, url, reason) from reason  # type: ignore[arg-type]
urllib3.exceptions.MaxRetryError: HTTPSConnectionPool(host='api.wandb.ai', port=443): Max retries exceeded with url: /graphql (Caused by ConnectTimeoutError(<urllib3.connection.HTTPSConnection object at 0x7f5f3778de40>, 'Connection to api.wandb.ai timed out. (connect timeout=20)'))

During handling of the above exception, another exception occurred:

Traceback (most recent call last):
  File "/home/fmri/miniconda3/envs/xt/lib/python3.10/site-packages/wandb/sdk/lib/retry.py", line 131, in __call__
    result = self._call_fn(*args, **kwargs)
  File "/home/fmri/miniconda3/envs/xt/lib/python3.10/site-packages/wandb/sdk/internal/internal_api.py", line 369, in execute
    return self.client.execute(*args, **kwargs)  # type: ignore
  File "/home/fmri/miniconda3/envs/xt/lib/python3.10/site-packages/wandb/vendor/gql-0.2.0/wandb_gql/client.py", line 52, in execute
    result = self._get_result(document, *args, **kwargs)
  File "/home/fmri/miniconda3/envs/xt/lib/python3.10/site-packages/wandb/vendor/gql-0.2.0/wandb_gql/client.py", line 60, in _get_result
    return self.transport.execute(document, *args, **kwargs)
  File "/home/fmri/miniconda3/envs/xt/lib/python3.10/site-packages/wandb/sdk/lib/gql_request.py", line 58, in execute
    request = self.session.post(self.url, **post_args)
  File "/home/fmri/miniconda3/envs/xt/lib/python3.10/site-packages/requests/sessions.py", line 637, in post
    return self.request("POST", url, data=data, json=json, **kwargs)
  File "/home/fmri/miniconda3/envs/xt/lib/python3.10/site-packages/requests/sessions.py", line 589, in request
    resp = self.send(prep, **send_kwargs)
  File "/home/fmri/miniconda3/envs/xt/lib/python3.10/site-packages/requests/sessions.py", line 703, in send
    r = adapter.send(request, **kwargs)
  File "/home/fmri/miniconda3/envs/xt/lib/python3.10/site-packages/requests/adapters.py", line 688, in send
    raise ConnectTimeout(e, request=request)
requests.exceptions.ConnectTimeout: HTTPSConnectionPool(host='api.wandb.ai', port=443): Max retries exceeded with url: /graphql (Caused by ConnectTimeoutError(<urllib3.connection.HTTPSConnection object at 0x7f5f3778de40>, 'Connection to api.wandb.ai timed out. (connect timeout=20)'))
2024-07-17 09:53:08,324 DEBUG   HandlerThread:171558 [handler.py:handle_request():146] handle_request: keepalive
2024-07-17 09:53:09,525 DEBUG   HandlerThread:171558 [handler.py:handle_request():146] handle_request: shutdown
2024-07-17 09:53:09,525 INFO    HandlerThread:171558 [handler.py:finish():866] shutting down handler
2024-07-17 09:53:10,320 INFO    WriterThread:171558 [datastore.py:close():296] close: /media/SSD_1_2T/xt/MindBridge/src/wandb/run-20240717_095203-mi6gcdwu/run-mi6gcdwu.wandb
2024-07-17 09:55:12,383 INFO    SenderThread:171558 [dir_watcher.py:__init__():211] watching files in: /media/SSD_1_2T/xt/MindBridge/src/wandb/run-20240717_095203-mi6gcdwu/files
2024-07-17 09:55:12,389 INFO    SenderThread:171558 [sender.py:_start_run_threads():1124] run started: mi6gcdwu with start time 1721181123.309493
2024-07-17 09:55:12,389 INFO    SenderThread:171558 [sender.py:finish():1546] shutting down sender
2024-07-17 09:55:12,389 INFO    SenderThread:171558 [dir_watcher.py:finish():358] shutting down directory watcher
2024-07-17 09:55:13,383 INFO    SenderThread:171558 [dir_watcher.py:finish():388] scan: /media/SSD_1_2T/xt/MindBridge/src/wandb/run-20240717_095203-mi6gcdwu/files
2024-07-17 09:55:13,383 INFO    SenderThread:171558 [dir_watcher.py:finish():402] scan save: /media/SSD_1_2T/xt/MindBridge/src/wandb/run-20240717_095203-mi6gcdwu/files/config.yaml config.yaml
2024-07-17 09:55:13,383 INFO    SenderThread:171558 [file_pusher.py:finish():172] shutting down file pusher
2024-07-17 09:55:13,383 INFO    SenderThread:171558 [file_pusher.py:join():178] waiting for file pusher
2024-07-17 09:55:14,469 INFO    wandb-upload_0:171558 [upload_job.py:push():131] Uploaded file /media/SSD_1_2T/xt/MindBridge/src/wandb/run-20240717_095203-mi6gcdwu/files/config.yaml
2024-07-17 09:55:14,885 INFO    SenderThread:171558 [file_stream.py:finish():614] file stream finish called
2024-07-17 09:55:15,503 INFO    SenderThread:171558 [file_stream.py:finish():618] file stream finish is done
