2024-07-20 14:06:21,958 INFO    MainThread:1183890 [wandb_setup.py:_flush():76] Current SDK version is 0.16.6
2024-07-20 14:06:21,959 INFO    MainThread:1183890 [wandb_setup.py:_flush():76] Configure stats pid to 1183890
2024-07-20 14:06:21,959 INFO    MainThread:1183890 [wandb_setup.py:_flush():76] Loading settings from /home/fmri/.config/wandb/settings
2024-07-20 14:06:21,959 INFO    MainThread:1183890 [wandb_setup.py:_flush():76] Loading settings from /media/SSD_1_2T/xt/MindBridge/src/wandb/settings
2024-07-20 14:06:21,959 INFO    MainThread:1183890 [wandb_setup.py:_flush():76] Loading settings from environment variables: {'api_key': '***REDACTED***'}
2024-07-20 14:06:21,959 INFO    MainThread:1183890 [wandb_setup.py:_flush():76] Inferring run settings from compute environment: {'program_relpath': 'src/main.py', 'program_abspath': '/media/SSD_1_2T/xt/MindBridge/src/main.py', 'program': '/media/SSD_1_2T/xt/MindBridge/src/main.py'}
2024-07-20 14:06:21,959 INFO    MainThread:1183890 [wandb_setup.py:_flush():76] Applying login settings: {'base_url': 'https://api.wandb.ai'}
2024-07-20 14:06:21,959 INFO    MainThread:1183890 [wandb_setup.py:_flush():76] Applying login settings: {}
2024-07-20 14:06:21,959 INFO    MainThread:1183890 [wandb_init.py:_log_setup():521] Logging user logs to /media/SSD_1_2T/xt/MindBridge/src/wandb/run-20240720_140621-5bzl8sa2/logs/debug.log
2024-07-20 14:06:21,959 INFO    MainThread:1183890 [wandb_init.py:_log_setup():522] Logging internal logs to /media/SSD_1_2T/xt/MindBridge/src/wandb/run-20240720_140621-5bzl8sa2/logs/debug-internal.log
2024-07-20 14:06:21,959 INFO    MainThread:1183890 [wandb_init.py:init():561] calling init triggers
2024-07-20 14:06:21,959 INFO    MainThread:1183890 [wandb_init.py:init():568] wandb.init called with sweep_config: {}
config: {'trainer_select': 'trainer_fmri_img', 'model_name': 'MindBrige_image_only_mixco_loss', 'data_path': '/media/SSD_1_2T/xt/data/natural-scenes-dataset', 'subj_list': [1, 2, 5, 7], 'subj_source': [1], 'subj_target': [1], 'adapting': False, 'batch_size': 200, 'val_batch_size': 50, 'clip_variant': 'ViT-B/32', 'wandb_log': True, 'wandb_project': 'MindBrige_image_only_mixco_loss', 'resume': False, 'resume_id': None, 'load_from': None, 'norm_embs': True, 'use_image_aug': True, 'num_epochs': 500, 'lr_scheduler_type': 'cycle', 'ckpt_interval': 1, 'eval_interval': 1, 'h_size': 2048, 'n_blocks': 4, 'seed': 42, 'num_workers': 2, 'max_lr': 0.0005, 'mixup_pct': 0.2, 'pool_num': 8192, 'pool_type': 'max', 'mse_mult': 100000.0, 'mae_mult': 10000.0, 'cos_mult': 100.0, 'ssim_mult': 10000.0, 'rec_mult': 1.0, 'cyc_mult': 1.0, 'nce_mult': 1.0, 'clip_mult': 10, 'length': None, 'autoencoder_name': None, 'subj_load': None, 'subj_test': 1, 'samples': None, 'img2img_strength': 0.85, 'guidance_scale': 3.5, 'num_inference_steps': 20, 'recons_per_sample': 16, 'plotting': True, 'diffusion_cache_dir': '../weights', 'gpu_id': 0, 'ckpt_from': 'last', 'text_image_ratio': 0.5, 'test_start': 0, 'test_end': None, 'only_embeddings': False, 'synthesis': False, 'verbose': True, 'results_path': None}
2024-07-20 14:06:21,959 INFO    MainThread:1183890 [wandb_init.py:init():611] starting backend
2024-07-20 14:06:21,959 INFO    MainThread:1183890 [wandb_init.py:init():615] setting up manager
2024-07-20 14:06:21,961 INFO    MainThread:1183890 [backend.py:_multiprocessing_setup():105] multiprocessing start_methods=fork,spawn,forkserver, using: spawn
2024-07-20 14:06:21,962 INFO    MainThread:1183890 [wandb_init.py:init():623] backend started and connected
2024-07-20 14:06:21,964 INFO    MainThread:1183890 [wandb_init.py:init():715] updated telemetry
2024-07-20 14:06:21,967 INFO    MainThread:1183890 [wandb_init.py:init():748] communicating run to backend with 90.0 second timeout
2024-07-20 14:06:22,924 INFO    MainThread:1183890 [wandb_run.py:_on_init():2357] communicating current version
2024-07-20 14:06:27,927 INFO    MainThread:1183890 [wandb_run.py:_on_init():2366] got version response 
2024-07-20 14:06:27,932 INFO    MainThread:1183890 [wandb_init.py:init():799] starting run threads in backend
2024-07-20 14:06:29,153 INFO    MainThread:1183890 [wandb_run.py:_console_start():2335] atexit reg
2024-07-20 14:06:29,153 INFO    MainThread:1183890 [wandb_run.py:_redirect():2190] redirect: wrap_raw
2024-07-20 14:06:29,153 INFO    MainThread:1183890 [wandb_run.py:_redirect():2255] Wrapping output streams.
2024-07-20 14:06:29,153 INFO    MainThread:1183890 [wandb_run.py:_redirect():2280] Redirects installed.
2024-07-20 14:06:29,154 INFO    MainThread:1183890 [wandb_init.py:init():842] run started, returning control to user process
2024-07-20 14:07:20,345 INFO    Thread-1 (wrapped_target):1183890 [retry.py:__call__():172] Retry attempt failed:
Traceback (most recent call last):
  File "/home/fmri/miniconda3/envs/xt/lib/python3.10/site-packages/urllib3/connection.py", line 196, in _new_conn
    sock = connection.create_connection(
  File "/home/fmri/miniconda3/envs/xt/lib/python3.10/site-packages/urllib3/util/connection.py", line 85, in create_connection
    raise err
  File "/home/fmri/miniconda3/envs/xt/lib/python3.10/site-packages/urllib3/util/connection.py", line 73, in create_connection
    sock.connect(sa)
TimeoutError: timed out

The above exception was the direct cause of the following exception:

Traceback (most recent call last):
  File "/home/fmri/miniconda3/envs/xt/lib/python3.10/site-packages/urllib3/connectionpool.py", line 789, in urlopen
    response = self._make_request(
  File "/home/fmri/miniconda3/envs/xt/lib/python3.10/site-packages/urllib3/connectionpool.py", line 490, in _make_request
    raise new_e
  File "/home/fmri/miniconda3/envs/xt/lib/python3.10/site-packages/urllib3/connectionpool.py", line 466, in _make_request
    self._validate_conn(conn)
  File "/home/fmri/miniconda3/envs/xt/lib/python3.10/site-packages/urllib3/connectionpool.py", line 1095, in _validate_conn
    conn.connect()
  File "/home/fmri/miniconda3/envs/xt/lib/python3.10/site-packages/urllib3/connection.py", line 615, in connect
    self.sock = sock = self._new_conn()
  File "/home/fmri/miniconda3/envs/xt/lib/python3.10/site-packages/urllib3/connection.py", line 205, in _new_conn
    raise ConnectTimeoutError(
urllib3.exceptions.ConnectTimeoutError: (<urllib3.connection.HTTPSConnection object at 0x7f91938fa170>, 'Connection to api.wandb.ai timed out. (connect timeout=20)')

The above exception was the direct cause of the following exception:

Traceback (most recent call last):
  File "/home/fmri/miniconda3/envs/xt/lib/python3.10/site-packages/requests/adapters.py", line 667, in send
    resp = conn.urlopen(
  File "/home/fmri/miniconda3/envs/xt/lib/python3.10/site-packages/urllib3/connectionpool.py", line 843, in urlopen
    retries = retries.increment(
  File "/home/fmri/miniconda3/envs/xt/lib/python3.10/site-packages/urllib3/util/retry.py", line 519, in increment
    raise MaxRetryError(_pool, url, reason) from reason  # type: ignore[arg-type]
urllib3.exceptions.MaxRetryError: HTTPSConnectionPool(host='api.wandb.ai', port=443): Max retries exceeded with url: /graphql (Caused by ConnectTimeoutError(<urllib3.connection.HTTPSConnection object at 0x7f91938fa170>, 'Connection to api.wandb.ai timed out. (connect timeout=20)'))

During handling of the above exception, another exception occurred:

Traceback (most recent call last):
  File "/home/fmri/miniconda3/envs/xt/lib/python3.10/site-packages/wandb/sdk/lib/retry.py", line 131, in __call__
    result = self._call_fn(*args, **kwargs)
  File "/home/fmri/miniconda3/envs/xt/lib/python3.10/site-packages/wandb/sdk/internal/internal_api.py", line 369, in execute
    return self.client.execute(*args, **kwargs)  # type: ignore
  File "/home/fmri/miniconda3/envs/xt/lib/python3.10/site-packages/wandb/vendor/gql-0.2.0/wandb_gql/client.py", line 52, in execute
    result = self._get_result(document, *args, **kwargs)
  File "/home/fmri/miniconda3/envs/xt/lib/python3.10/site-packages/wandb/vendor/gql-0.2.0/wandb_gql/client.py", line 60, in _get_result
    return self.transport.execute(document, *args, **kwargs)
  File "/home/fmri/miniconda3/envs/xt/lib/python3.10/site-packages/wandb/sdk/lib/gql_request.py", line 58, in execute
    request = self.session.post(self.url, **post_args)
  File "/home/fmri/miniconda3/envs/xt/lib/python3.10/site-packages/requests/sessions.py", line 637, in post
    return self.request("POST", url, data=data, json=json, **kwargs)
  File "/home/fmri/miniconda3/envs/xt/lib/python3.10/site-packages/requests/sessions.py", line 589, in request
    resp = self.send(prep, **send_kwargs)
  File "/home/fmri/miniconda3/envs/xt/lib/python3.10/site-packages/requests/sessions.py", line 703, in send
    r = adapter.send(request, **kwargs)
  File "/home/fmri/miniconda3/envs/xt/lib/python3.10/site-packages/requests/adapters.py", line 688, in send
    raise ConnectTimeout(e, request=request)
requests.exceptions.ConnectTimeout: HTTPSConnectionPool(host='api.wandb.ai', port=443): Max retries exceeded with url: /graphql (Caused by ConnectTimeoutError(<urllib3.connection.HTTPSConnection object at 0x7f91938fa170>, 'Connection to api.wandb.ai timed out. (connect timeout=20)'))
2024-07-20 14:48:17,514 WARNING MsgRouterThr:1183890 [router.py:message_loop():77] message_loop has been closed
