2024-07-17 08:47:52,911 INFO    StreamThr :17196 [internal.py:wandb_internal():86] W&B internal server running at pid: 17196, started at: 2024-07-17 08:47:52.911258
2024-07-17 08:47:52,912 DEBUG   HandlerThread:17196 [handler.py:handle_request():146] handle_request: status
2024-07-17 08:47:52,913 INFO    WriterThread:17196 [datastore.py:open_for_write():87] open: /media/SSD_1_2T/xt/MindBridge/src/wandb/run-20240717_084752-09ijmurm/run-09ijmurm.wandb
2024-07-17 08:47:52,913 DEBUG   SenderThread:17196 [sender.py:send():379] send: header
2024-07-17 08:47:52,914 DEBUG   SenderThread:17196 [sender.py:send():379] send: run
2024-07-17 08:47:57,915 DEBUG   HandlerThread:17196 [handler.py:handle_request():146] handle_request: keepalive
2024-07-17 08:48:02,916 DEBUG   HandlerThread:17196 [handler.py:handle_request():146] handle_request: keepalive
2024-07-17 08:48:07,916 DEBUG   HandlerThread:17196 [handler.py:handle_request():146] handle_request: keepalive
2024-07-17 08:48:12,917 DEBUG   HandlerThread:17196 [handler.py:handle_request():146] handle_request: keepalive
2024-07-17 08:48:17,918 DEBUG   HandlerThread:17196 [handler.py:handle_request():146] handle_request: keepalive
2024-07-17 08:48:22,919 DEBUG   HandlerThread:17196 [handler.py:handle_request():146] handle_request: keepalive
2024-07-17 08:48:27,920 DEBUG   HandlerThread:17196 [handler.py:handle_request():146] handle_request: keepalive
2024-07-17 08:48:32,921 DEBUG   HandlerThread:17196 [handler.py:handle_request():146] handle_request: keepalive
2024-07-17 08:48:37,922 DEBUG   HandlerThread:17196 [handler.py:handle_request():146] handle_request: keepalive
2024-07-17 08:48:42,923 DEBUG   HandlerThread:17196 [handler.py:handle_request():146] handle_request: keepalive
2024-07-17 08:48:47,924 DEBUG   HandlerThread:17196 [handler.py:handle_request():146] handle_request: keepalive
2024-07-17 08:48:51,866 DEBUG   HandlerThread:17196 [handler.py:handle_request():146] handle_request: shutdown
2024-07-17 08:48:51,867 INFO    HandlerThread:17196 [handler.py:finish():866] shutting down handler
2024-07-17 08:48:51,920 INFO    WriterThread:17196 [datastore.py:close():296] close: /media/SSD_1_2T/xt/MindBridge/src/wandb/run-20240717_084752-09ijmurm/run-09ijmurm.wandb
2024-07-17 08:48:56,227 INFO    SenderThread:17196 [retry.py:__call__():172] Retry attempt failed:
Traceback (most recent call last):
  File "/home/fmri/miniconda3/envs/xt/lib/python3.10/site-packages/urllib3/connection.py", line 196, in _new_conn
    sock = connection.create_connection(
  File "/home/fmri/miniconda3/envs/xt/lib/python3.10/site-packages/urllib3/util/connection.py", line 85, in create_connection
    raise err
  File "/home/fmri/miniconda3/envs/xt/lib/python3.10/site-packages/urllib3/util/connection.py", line 73, in create_connection
    sock.connect(sa)
TimeoutError: timed out

The above exception was the direct cause of the following exception:

Traceback (most recent call last):
  File "/home/fmri/miniconda3/envs/xt/lib/python3.10/site-packages/urllib3/connectionpool.py", line 789, in urlopen
    response = self._make_request(
  File "/home/fmri/miniconda3/envs/xt/lib/python3.10/site-packages/urllib3/connectionpool.py", line 490, in _make_request
    raise new_e
  File "/home/fmri/miniconda3/envs/xt/lib/python3.10/site-packages/urllib3/connectionpool.py", line 466, in _make_request
    self._validate_conn(conn)
  File "/home/fmri/miniconda3/envs/xt/lib/python3.10/site-packages/urllib3/connectionpool.py", line 1095, in _validate_conn
    conn.connect()
  File "/home/fmri/miniconda3/envs/xt/lib/python3.10/site-packages/urllib3/connection.py", line 615, in connect
    self.sock = sock = self._new_conn()
  File "/home/fmri/miniconda3/envs/xt/lib/python3.10/site-packages/urllib3/connection.py", line 205, in _new_conn
    raise ConnectTimeoutError(
urllib3.exceptions.ConnectTimeoutError: (<urllib3.connection.HTTPSConnection object at 0x7f6c04e4de40>, 'Connection to api.wandb.ai timed out. (connect timeout=20)')

The above exception was the direct cause of the following exception:

Traceback (most recent call last):
  File "/home/fmri/miniconda3/envs/xt/lib/python3.10/site-packages/requests/adapters.py", line 667, in send
    resp = conn.urlopen(
  File "/home/fmri/miniconda3/envs/xt/lib/python3.10/site-packages/urllib3/connectionpool.py", line 843, in urlopen
    retries = retries.increment(
  File "/home/fmri/miniconda3/envs/xt/lib/python3.10/site-packages/urllib3/util/retry.py", line 519, in increment
    raise MaxRetryError(_pool, url, reason) from reason  # type: ignore[arg-type]
urllib3.exceptions.MaxRetryError: HTTPSConnectionPool(host='api.wandb.ai', port=443): Max retries exceeded with url: /graphql (Caused by ConnectTimeoutError(<urllib3.connection.HTTPSConnection object at 0x7f6c04e4de40>, 'Connection to api.wandb.ai timed out. (connect timeout=20)'))

During handling of the above exception, another exception occurred:

Traceback (most recent call last):
  File "/home/fmri/miniconda3/envs/xt/lib/python3.10/site-packages/wandb/sdk/lib/retry.py", line 131, in __call__
    result = self._call_fn(*args, **kwargs)
  File "/home/fmri/miniconda3/envs/xt/lib/python3.10/site-packages/wandb/sdk/internal/internal_api.py", line 369, in execute
    return self.client.execute(*args, **kwargs)  # type: ignore
  File "/home/fmri/miniconda3/envs/xt/lib/python3.10/site-packages/wandb/vendor/gql-0.2.0/wandb_gql/client.py", line 52, in execute
    result = self._get_result(document, *args, **kwargs)
  File "/home/fmri/miniconda3/envs/xt/lib/python3.10/site-packages/wandb/vendor/gql-0.2.0/wandb_gql/client.py", line 60, in _get_result
    return self.transport.execute(document, *args, **kwargs)
  File "/home/fmri/miniconda3/envs/xt/lib/python3.10/site-packages/wandb/sdk/lib/gql_request.py", line 58, in execute
    request = self.session.post(self.url, **post_args)
  File "/home/fmri/miniconda3/envs/xt/lib/python3.10/site-packages/requests/sessions.py", line 637, in post
    return self.request("POST", url, data=data, json=json, **kwargs)
  File "/home/fmri/miniconda3/envs/xt/lib/python3.10/site-packages/requests/sessions.py", line 589, in request
    resp = self.send(prep, **send_kwargs)
  File "/home/fmri/miniconda3/envs/xt/lib/python3.10/site-packages/requests/sessions.py", line 703, in send
    r = adapter.send(request, **kwargs)
  File "/home/fmri/miniconda3/envs/xt/lib/python3.10/site-packages/requests/adapters.py", line 688, in send
    raise ConnectTimeout(e, request=request)
requests.exceptions.ConnectTimeout: HTTPSConnectionPool(host='api.wandb.ai', port=443): Max retries exceeded with url: /graphql (Caused by ConnectTimeoutError(<urllib3.connection.HTTPSConnection object at 0x7f6c04e4de40>, 'Connection to api.wandb.ai timed out. (connect timeout=20)'))
2024-07-17 08:49:02,592 INFO    SenderThread:17196 [dir_watcher.py:__init__():211] watching files in: /media/SSD_1_2T/xt/MindBridge/src/wandb/run-20240717_084752-09ijmurm/files
2024-07-17 08:49:02,592 INFO    SenderThread:17196 [sender.py:_start_run_threads():1124] run started: 09ijmurm with start time 1721177272.910687
2024-07-17 08:49:02,592 INFO    SenderThread:17196 [sender.py:finish():1546] shutting down sender
2024-07-17 08:49:02,592 INFO    SenderThread:17196 [dir_watcher.py:finish():358] shutting down directory watcher
2024-07-17 08:49:03,592 INFO    SenderThread:17196 [dir_watcher.py:finish():388] scan: /media/SSD_1_2T/xt/MindBridge/src/wandb/run-20240717_084752-09ijmurm/files
2024-07-17 08:49:03,592 INFO    SenderThread:17196 [dir_watcher.py:finish():402] scan save: /media/SSD_1_2T/xt/MindBridge/src/wandb/run-20240717_084752-09ijmurm/files/config.yaml config.yaml
2024-07-17 08:49:03,592 INFO    SenderThread:17196 [file_pusher.py:finish():172] shutting down file pusher
2024-07-17 08:49:03,592 INFO    SenderThread:17196 [file_pusher.py:join():178] waiting for file pusher
2024-07-17 08:49:04,656 INFO    wandb-upload_0:17196 [upload_job.py:push():131] Uploaded file /media/SSD_1_2T/xt/MindBridge/src/wandb/run-20240717_084752-09ijmurm/files/config.yaml
2024-07-17 08:49:05,094 INFO    SenderThread:17196 [file_stream.py:finish():614] file stream finish called
2024-07-17 08:49:05,697 INFO    SenderThread:17196 [file_stream.py:finish():618] file stream finish is done
